File: WrightTools/datasets/LabRAM/spectrum_nm.txt
#Acq. time (s)=	2
#Accumulations=	2
#Range (nm)=	425...625
#Windows=	5
#Auto scanning=	On
#Autofocus=	Off
#Macrospot=	Off
#AutoExposure=	Off
#Spike filter=	Multiple accum.
#Delay time (s)=	1
#Binning=	1
#Readout mode=	Signal
#DeNoise=	Off
#ICS correction=	On
#Dark correction=	Off
#Inst. Process=	Off
#Detector Gain=	High Sensitivity
#Detector ADC=	20 kHz
#Detector temperature (°C)=	-75.07
#Instrument=	LabRAM HR Evol
#Detector=	Synapse BIDD
#Objective=	x50
#Grating=	300 gr/mm
#ND Filter=	0.01%
#Laser (nm)=	405
#Hole=	100.021
#Temperature=	0
#Range=	Auto
#Laser Pol.=	No
#Raman. Pol.=	No
#Laser Pol. (°)=	0
#Raman Pol. (°)=	0.008
#StageXY=	Marzhauser
#StageZ=	Marzhauser
#X (µm)=	0
#Y (µm)=	0
#Z (µm)=	0
#Full time(s)=	48
#Project=
#Sample=
#Site=
#Title=	xBr85_1
#Remark=
#Date=	24.06.2021 15:54
#Acquired=	24.06.2021 15:54:31
425.071	116.535
425.285	115.757
425.499	118.564
425.713	109.336
425.927	100.888
426.141	114.761
426.355	114.823
426.569	98.4398
426.783	97.0754
426.997	105.873
427.211	96.2188
427.425	94.7914
427.639	102.076
427.854	110.233
428.068	113.257
428.282	108.597
428.496	92.0326
428.71	104.35
428.924	114.49
429.138	79.8308
429.352	101.95
429.566	105.512
429.78	102.829
429.994	97.4238
430.208	98.339
430.422	80.836
430.636	86.961
430.85	76.6529
431.064	91.1528
431.278	92.4029
431.492	86.4605
431.706	103.192
431.92	98.1525
432.134	90.446
432.348	97.1198
432.562	91.1563
432.776	83.4902
432.99	90.7081
433.204	75.2795
433.418	70.7693
433.632	82.207
433.846	95.9448
434.06	96.2842
434.274	67.3082
434.488	84.7118
434.702	70.6678
434.916	79.8359
435.13	77.4402
435.344	86.7343
435.558	75.4861
435.772	70.7075
435.986	83.3635
436.2	85.5142
436.414	72.5903
436.628	76.8924
436.842	68.4369
437.056	78.4294
437.27	73.106
437.484	71.9813
437.698	75.7377
437.912	65.2121
438.126	72.5718
438.34	76.245
438.554	70.311
438.768	74.1469
438.982	61.8616
439.195	79.5245
439.409	73.5405
439.623	65.2875
439.837	64.5765
440.051	70.8538
440.265	72.8773
440.479	58.6718
440.693	67.033
440.907	64.7246
441.121	67.3748
441.335	69.2421
441.549	76.213
441.763	70.0555
441.976	70.1208
442.19	67.8112
442.404	59.5656
442.618	73.6724
442.832	53.8364
443.046	79.5123
443.26	67.4816
443.474	58.1891
443.688	66.5048
443.901	74.4702
444.115	79.5483
444.329	63.0321
444.543	56.7259
444.757	53.9357
444.971	64.649
445.185	55.8557
445.398	64.0352
445.612	47.4031
445.826	63.4231
446.04	63.3699
446.254	65.4128
446.468	59.1619
446.682	53.1905
446.895	49.9048
447.109	59.7588
447.323	60.8807
447.537	60.9421
447.751	61.8052
447.965	53.1878
448.178	59.0686
448.392	52.6391
448.606	64.8513
448.82	50.5615
449.034	60.0791
449.248	53.9436
449.461	55.454
449.675	65.0721
449.889	41.2982
450.103	64.355
450.317	55.7596
450.53	44.9581
450.744	56.3557
450.958	60.2246
451.172	53.6414
451.386	57.1596
451.599	62.8238
451.813	51.1405
452.027	50.8726
452.241	58.3206
452.454	55.4413
452.668	44.1923
452.882	46.3473
453.096	53.0466
453.31	50.6456
453.523	49.2564
453.737	43.3857
453.951	41.588
454.165	39.9538
454.378	53.9528
454.592	46.7606
454.806	45.9982
455.02	49.8412
455.233	53.3675
455.447	49.0289
455.661	50.8089
455.875	47.4125
456.088	45.6481
456.302	48.8649
456.516	42.6218
456.729	46.9511
456.943	39.983
457.157	46.0069
457.371	49.4247
457.584	40.5531
457.798	40.2931
458.012	47.833
458.225	43.3193
458.439	46.2152
458.653	41.4975
458.866	49.4232
459.08	44.9159
459.294	37.3178
459.508	43.2323
459.721	43.33
459.935	44.2614
460.149	39.5538
460.362	51.2103
460.576	43.9071
460.79	44.8645
461.003	44.814
461.217	43.6464
461.431	38.4081
461.644	44.7555
461.858	44.5194
462.072	47.0433
462.285	45.8206
462.499	46.6385
462.712	45.3042
462.926	44.1615
463.14	39.0835
463.353	39.0131
463.567	41.8031
463.781	42.1357
463.994	39.909
464.208	39.1826
464.422	47.6058
464.635	37.5258
464.849	43.1664
465.062	40.8202
465.276	42.8299
465.49	35.2228
465.703	42.6425
465.917	36.9841
466.13	39.9433
466.344	37.2705
466.558	41.8721
466.771	38.1597
466.985	36.6321
467.198	42.4239
467.412	46.0024
467.626	40.9852
467.839	45.2891
468.053	45.5987
468.266	34.2038
468.48	37.2932
468.693	44.5083
468.907	37.9037
469.12	42.6161
469.334	40.1803
469.548	43.4657
469.761	38.3083
469.975	38.9082
470.188	47.5786
470.402	41.7766
470.615	42.0256
470.829	40.315
471.042	39.1827
471.256	46.5278
471.469	41.395
471.683	43.7976
471.897	39.1234
472.11	40.4952
472.324	41.0898
472.537	41.9794
472.751	44.4396
472.964	44.0338
473.178	42.6768
473.391	46.4806
473.605	37.8266
473.818	41.3771
474.032	39.7357
474.245	39.126
474.459	40.9527
474.672	49.3635
474.885	42.2224
475.099	47.9235
475.312	41.3166
475.526	45.76
475.739	39.2219
475.953	38.1922
476.166	46.0558
476.38	42.0013
476.593	46.6413
476.807	43.2124
477.02	49.7905
477.234	43.8598
477.447	47.5738
477.66	47.408
477.874	44.7676
478.087	56.0902
478.301	42.5126
478.514	48.036
478.728	42.6069
478.941	51.462
479.154	48.1647
479.368	43.6208
479.581	58.2623
479.736	48.1962
479.95	38.5386
480.164	54.3125
480.378	44.8858
480.592	46.2904
480.805	43.1594
481.019	58.7742
481.233	51.0341
481.447	50.925
481.66	68.707
481.874	57.8497
482.088	53.8253
482.302	51.8339
482.515	51.8687
482.729	55.3136
482.943	45.1612
483.157	55.3977
483.37	59.112
483.584	53.9881
483.798	51.8345
484.012	65.8593
484.225	66.2816
484.439	59.4524
484.653	51.516
484.867	53.0353
485.08	63.1087
485.294	62.2668
485.508	56.1408
485.722	70.6577
485.935	53.0625
486.149	67.5673
486.363	68.0067
486.576	51.7133
486.79	52.2668
487.004	65.1612
487.217	69.9345
487.431	58.4445
487.645	60.2338
487.859	61.3471
488.072	73.925
488.286	75.0404
488.5	73.2867
488.713	71.1923
488.927	78.488
489.141	70.2408
489.354	77.0988
489.568	71.9864
489.782	82.095
489.995	81.7368
490.209	71.4108
490.423	71.3558
490.636	80.3885
490.85	88.6649
491.064	82.068
491.277	77.3791
491.491	79.4896
491.705	71.4457
491.918	69.7619
492.132	73.785
492.346	81.0537
492.559	83.4251
492.773	77.3765
492.987	75.9855
493.2	77.3956
493.414	82.4827
493.627	84.425
493.841	92.1288
494.055	95.4676
494.268	90.8296
494.482	91.6034
494.696	85.6684
494.909	86.5699
495.123	95.2879
495.336	77.9101
495.55	87.213
495.764	88.1197
495.977	87.6167
496.191	85.8127
496.404	78.9702
496.618	89.1833
496.832	92.5182
497.045	94.103
497.259	92.9393
497.472	91.8487
497.686	94.7676
497.899	93.2087
498.113	88.8464
498.327	94.9826
498.54	93.0112
498.754	104.312
498.967	107.455
499.181	98.1631
499.394	102.988
499.608	92.3299
499.821	105.246
500.035	106.013
500.249	94.4985
500.462	111.286
500.676	98.9804
500.889	101.779
501.103	105.287
501.316	104.448
501.53	105.98
501.743	104.6
501.957	108.05
502.17	110.276
502.384	106.166
502.597	106.372
502.811	111.305
503.024	111.19
503.238	108.633
503.451	115.148
503.665	108.008
503.878	109.595
504.092	111.88
504.305	113.787
504.519	106.908
504.732	108.19
504.946	112.885
505.159	100.144
505.373	111.179
505.586	108.004
505.8	100.471
506.013	108.838
506.227	106.215
506.44	113.447
506.654	109.9
506.867	112.276
507.081	111.35
507.294	114.111
507.507	105.14
507.721	115.621
507.934	100.729
508.148	105.779
508.361	100.51
508.575	102.539
508.788	109.493
509.002	104.872
509.215	94.4216
509.428	97.8987
509.642	102.355
509.855	104.528
510.069	106.07
510.282	95.0507
510.495	100.932
510.709	105.792
510.922	97.5773
511.136	101.477
511.349	97.4323
511.563	102.611
511.776	106.142
511.989	100.295
512.203	104.522
512.416	99.2164
512.629	99.0366
512.843	91.4605
513.056	101.509
513.27	101.117
513.483	92.9518
513.696	95.991
513.91	97.9861
514.123	91.9996
514.336	88.8062
514.55	94.6719
514.763	93.4868
514.977	92.5699
515.19	89.9255
515.403	95.0518
515.617	80.9495
515.83	93.3318
516.043	88.6959
516.257	85.162
516.47	85.4016
516.683	80.7083
516.897	83.0281
517.11	86.7028
517.323	80.9257
517.536	83.665
517.75	82.1154
517.963	70.2095
518.176	85.6688
518.39	76.5435
518.603	76.8873
518.816	74.2893
519.03	74.7171
519.243	78.7314
519.456	78.1923
519.669	71.0147
519.883	75.0987
520.096	69.9531
520.309	75.6617
520.523	74.1303
520.736	72.1733
520.949	79.8303
521.162	69.5865
521.376	65.7178
521.589	61.6079
521.802	73.9451
522.016	66.2309
522.229	65.6042
522.442	66.4053
522.655	67.2674
522.868	72.6202
523.082	72.0624
523.295	68.3058
523.508	59.8811
523.721	57.46
523.935	59.1146
524.148	54.4888
524.361	68.6552
524.574	53.3204
524.788	59.891
525.001	57.0637
525.214	55.4895
525.427	57.7818
525.64	54.4365
525.854	58.1002
526.067	53.6138
526.28	48.8542
526.493	54.0165
526.706	60.7464
526.92	51.6863
527.133	53.6505
527.346	56.7441
527.559	51.3484
527.772	59.6288
527.985	51.6673
528.199	52.1503
528.412	50.9283
528.625	46.4259
528.838	51.3763
529.051	53.0831
529.264	49.9213
529.478	53.9475
529.691	44.7636
529.904	50.8594
530.117	41.5337
530.33	45.1485
530.543	47.4556
530.756	42.2116
530.97	52.6597
531.183	46.0314
531.396	43.0449
531.609	46.5594
531.822	40.155
532.035	43.3161
532.248	42.0795
532.461	44.3595
532.674	44.6176
532.888	41.9287
533.101	43.0078
533.314	44.2961
533.527	45.1682
533.74	44.3144
533.953	43.3318
534.128	48.2224
534.341	47.3144
534.555	44.2847
534.768	45.2109
534.981	30.4266
535.195	43.2877
535.408	35.5556
535.622	39.2195
535.835	38.4026
536.049	40.198
536.262	44.6232
536.476	39.2128
536.689	33.4694
536.903	29.6537
537.116	40.3279
537.329	38.2468
537.543	37.2704
537.756	39.9116
537.97	38.0561
538.183	36.5625
538.397	31.9606
538.61	34.1579
538.823	39.1269
539.037	38.9627
539.25	38.2218
539.464	38.3594
539.677	40.1905
539.89	38.9357
540.104	38.5113
540.317	32.4043
540.531	37.8873
540.744	34.6308
540.957	29.9718
541.171	28.7781
541.384	26.5069
541.598	31.4478
541.811	35.5286
542.024	36.192
542.238	32.3131
542.451	27.5881
542.664	26.6121
542.878	31.6531
543.091	29.7747
543.305	28.6625
543.518	33.8747
543.731	34.0574
543.945	31.178
544.158	31.8479
544.371	27.9775
544.585	30.7097
544.798	32.218
545.011	30.0774
545.225	28.4696
545.438	28.2934
545.651	27.1366
545.865	26.6859
546.078	26.7479
546.291	25.5813
546.505	28.9846
546.718	26.9779
546.931	31.6371
547.145	27.3028
547.358	31.1278
547.571	26.0738
547.785	26.9327
547.998	24.9049
548.211	30.1867
548.424	27.6004
548.638	28.1456
548.851	24.0585
549.064	27.208
549.278	24.1269
549.491	29.4909
549.704	26.949
549.918	25.3888
550.131	24.7126
550.344	24.7869
550.557	28.9358
550.771	28.9903
550.984	30.1271
551.197	25.1019
551.41	27.0994
551.624	22.6244
551.837	25.2529
552.05	28.1252
552.263	26.8921
552.477	23.6961
552.69	22.1651
552.903	25.0997
553.116	21.5609
553.33	25.0766
553.543	25.9778
553.756	27.0072
553.969	23.1503
554.183	25.2698
554.396	25.3283
554.609	21.3188
554.822	23.1193
555.035	23.3729
555.249	28.212
555.462	23.253
555.675	24.6285
555.888	21.5847
556.101	23.8062
556.315	25.5753
556.528	23.7946
556.741	22.4526
556.954	24.5572
557.167	25.2532
557.381	22.0788
557.594	24.1635
557.807	24.74
558.02	21.3912
558.233	24.5322
558.446	22.1385
558.66	25.3156
558.873	23.6398
559.086	24.6102
559.299	25.0657
559.512	22.5693
559.725	21.7378
559.939	21.373
560.152	23.8036
560.365	23.5635
560.578	21.0894
560.791	23.9304
561.004	23.674
561.217	22.2736
561.43	23.3041
561.644	23.9942
561.857	23.5999
562.07	20.8805
562.283	21.2039
562.496	21.0572
562.709	20.4939
562.922	22.597
563.135	18.042
563.349	19.5992
563.562	19.9199
563.775	21.9027
563.988	18.4821
564.201	22.8032
564.414	22.0159
564.627	21.6216
564.84	18.6317
565.053	18.3597
565.266	21.9156
565.479	22.9222
565.692	19.9375
565.906	19.2732
566.119	22.0647
566.332	19.8145
566.545	25.9587
566.758	20.9954
566.971	24.2338
567.184	18.9611
567.397	22.7086
567.61	18.8073
567.823	21.0903
568.036	20.9299
568.249	16.9297
568.462	21.1916
568.675	20.274
568.888	20.9738
569.101	18.3567
569.314	21.6215
569.527	22.4292
569.74	19.7063
569.953	17.7599
570.166	19.1107
570.379	17.2824
570.592	22.0852
570.805	21.1308
571.018	22.9707
571.231	20.512
571.444	15.8454
571.657	19.3974
571.87	15.8071
572.083	19.8876
572.296	20.3233
572.509	14.8607
572.722	19.7585
572.935	16.8944
573.148	18.1338
573.361	17.0316
573.574	17.7948
573.787	18.9411
574	18.7228
574.213	20.7483
574.426	17.8429
574.639	17.4259
574.852	20.8165
575.065	17.8106
575.277	16.7883
575.49	18.3284
575.703	16.7918
575.916	18.2814
576.129	18.9067
576.342	18.3559
576.555	17.8391
576.768	19.9689
576.981	19.3899
577.194	18.1209
577.407	21.1936
577.62	13.3162
577.832	18.7133
578.045	18.4354
578.258	17.181
578.471	16.8442
578.684	16.6283
578.897	17.9458
579.11	18.3891
579.323	17.1398
579.536	18.9553
579.748	19.9925
579.961	20.0512
580.174	17.1191
580.387	16.6342
580.6	20.2352
580.813	21.1318
581.026	20.4331
581.238	18.5098
581.451	20.2946
581.664	21.333
581.877	20.5521
582.09	16.0774
582.303	18.4027
582.515	18.3129
582.728	19.7713
582.941	19.3105
583.154	13.9466
583.367	17.8765
583.579	14.9765
583.792	16.8799
584.005	15.609
584.218	17.1647
584.431	17.6784
584.643	20.3575
584.856	21.9842
585.069	20.2716
585.282	18.5229
585.495	17.2142
585.707	17.5023
585.92	16.6275
586.133	15.8801
586.346	16.6603
586.559	14.6604
586.771	16.6793
586.984	16.0204
587.197	16.9493
587.41	16.6133
587.622	17.8385
587.835	16.9641
588.048	13.5218
588.261	15.4666
588.388	17.239
588.601	16.3978
588.814	23.6735
589.027	19.4612
589.241	17.1509
589.454	17.9394
589.667	16.2628
589.88	16.4217
590.093	13.9879
590.306	18.2147
590.519	20.4324
590.732	16.8605
590.946	16.6217
591.159	18.957
591.372	15.768
591.585	14.3885
591.798	18.9105
592.011	15.0854
592.224	14.3542
592.437	17.1258
592.65	16.0762
592.863	16.7606
593.077	13.8318
593.29	19.1019
593.503	16.3252
593.716	12.9858
593.929	18.4669
594.142	15.7341
594.355	17.577
594.568	18.0212
594.781	15.9046
594.994	16.9029
595.207	15.4063
595.42	14.5098
595.633	18.1054
595.846	14.2938
596.06	15.9885
596.273	12.4652
596.486	13.9012
596.699	17.9273
596.912	12.9663
597.125	20.2798
597.338	15.4424
597.551	16.9445
597.764	14.9444
597.977	15.3119
598.19	13.9362
598.403	17.3176
598.616	14.0701
598.829	13.2993
599.042	15.2351
599.255	19.1649
599.468	16.5388
599.681	16.7328
599.894	13.5674
600.107	11.7871
600.32	15.7693
600.533	14.4477
600.746	15.7967
600.959	16.8867
601.172	18.0406
601.385	14.613
601.598	17.4703
601.811	14.518
602.024	18.6222
602.237	16.4142
602.45	13.6036
602.663	17.6941
602.876	15.6935
603.089	18.7271
603.302	14.3662
603.515	16.3405
603.727	14.4058
603.94	15.607
604.153	16.1201
604.366	15.3961
604.579	16.1652
604.792	16.4539
605.005	16.8721
605.218	14.4616
605.431	14.733
605.644	16.3769
605.857	16.0816
606.07	11.2414
606.283	17.1392
606.496	15.6201
606.708	15.2796
606.921	17.0727
607.134	15.9082
607.347	12.9222
607.56	14.49
607.773	17.7281
607.986	15.5782
608.199	15.5486
608.412	14.127
608.625	15.2245
608.837	15.6807
609.05	15.3557
609.263	14.7793
609.476	13.4879
609.689	16.6723
609.902	16.4017
610.115	17.0096
610.327	14.4747
610.54	17.3096
610.753	18.5325
610.966	15.4275
611.179	15.7039
611.392	14.3893
611.605	13.6921
611.817	16.2249
612.03	14.4089
612.243	15.6693
612.456	13.0275
612.669	14.3203
612.882	15.7899
613.094	17.759
613.307	14.1677
613.52	15.0869
613.733	16.1257
613.946	13.8105
614.158	15.3774
614.371	18.8281
614.584	15.6128
614.797	12.9706
615.01	15.9172
615.222	17.4677
615.435	14.5468
615.648	15.8438
615.861	16.1212
616.074	15.9744
616.286	14.8128
616.499	14.6507
616.712	14.8328
616.925	16.4294
617.137	17.4069
617.35	16.4847
617.563	14.1957
617.776	15.8489
617.988	15.3837
618.201	15.8595
618.414	15.353
618.627	16.7519
618.839	13.1082
619.052	16.8528
619.265	14.2645
619.478	13.579
619.69	15.6895
619.903	15.9763
620.116	13.9149
620.328	15.4001
620.541	14.9714
620.754	13.8425
620.967	16.2041
621.179	13.851
621.392	18.1148
621.605	16.9691
621.817	13.9943
622.03	14.1173
622.243	15.5178
622.456	13.7234
622.668	12.1342
622.881	15.5941
623.094	13.4185
623.306	14.8264
623.519	15.0563
623.732	15.0081
623.944	14.9148
624.157	13.2697
624.37	14.6472
624.582	14.4225
624.795	14.1673
624.94	14.298